29511007
66215773
8955492



385389247
8963223
26663023
26663020
394286248



149436519
240577405
8969746


8950342
5050016


8941572


304467425
64866716


5018668
58674683
24217961



three subway

304467425
000975_000304467425


8941572
000181_000008941572


8950342
000270_000008950342

python download_image_with_zoom.py 
Traceback (most recent call last):
  File "download_image_with_zoom.py", line 84, in <module>
    download_photo(tmp_node, way_index, way_id, i)
  File "download_image_with_zoom.py", line 60, in download_photo
    save_photo(photo_url, photo_dir, photo_name)
  File "download_image_with_zoom.py", line 31, in save_photo
    fjpg.write(urllib2.urlopen(photo_url).read())
  File "/usr/lib/python2.7/urllib2.py", line 127, in urlopen
    return _opener.open(url, data, timeout)
  File "/usr/lib/python2.7/urllib2.py", line 404, in open
    response = self._open(req, data)
  File "/usr/lib/python2.7/urllib2.py", line 422, in _open
    '_open', req)
  File "/usr/lib/python2.7/urllib2.py", line 382, in _call_chain
    result = func(*args)
  File "/usr/lib/python2.7/urllib2.py", line 1222, in https_open
    return self.do_open(httplib.HTTPSConnection, req)
  File "/usr/lib/python2.7/urllib2.py", line 1184, in do_open
    raise URLError(err)
urllib2.URLError: <urlopen error [Errno 104] Connection reset by peer>




Traceback (most recent call last):
  File "download_image_with_zoom.py", line 86, in <module>
    download_photo(tmp_node, way_index, way_id, i)
  File "download_image_with_zoom.py", line 62, in download_photo
    save_photo(photo_url, photo_dir, photo_name)
  File "download_image_with_zoom.py", line 33, in save_photo
    fjpg.write(urllib2.urlopen(photo_url).read())
  File "/usr/lib/python2.7/urllib2.py", line 127, in urlopen
    return _opener.open(url, data, timeout)
  File "/usr/lib/python2.7/urllib2.py", line 410, in open
    response = meth(req, response)
  File "/usr/lib/python2.7/urllib2.py", line 523, in http_response
    'http', request, response, code, msg, hdrs)
  File "/usr/lib/python2.7/urllib2.py", line 448, in error
    return self._call_chain(*args)
  File "/usr/lib/python2.7/urllib2.py", line 382, in _call_chain
    result = func(*args)
  File "/usr/lib/python2.7/urllib2.py", line 531, in http_error_default
    raise HTTPError(req.get_full_url(), code, msg, hdrs, fp)
urllib2.HTTPError: HTTP Error 500: Internal Server Error
